Workbook
Name _מולטימדיה: #REF!
Name מולטימדיה: #REF!
Name תקין: #REF!

Sheet הסבר על הטופס
D2: קובץ לבדיקות נגישות לתכני אינטרנט
D4: לפי תקנות שוויון זכויות לאנשים עם מוגבלות (התאמות נגישות לשירות), התשע"ג – 2013 (סימן ג' תקנה 35) (להלן – התקנות)
D6: הנחיות לשימוש בקובץ
D8: קובץ זה כולל גיליון לבדיקת נגישות לאינטרנט (check list). הבדיקה תתבצע על מידע או שירותים הניתנים באמצעות האינטרנט, לרבות, דפים באתר, מסמכים (כגון PDF ו Word) וישומים.
D9: התקנות מחייבות מילוי גיליון בדיקה שמפרסם נציב שוויון זכויות לאנשים עם מוגבלות (תקנה 93 (א)) - חובה למלא טופס זה.
D10: הבדיקה תתבצע עבור כל תבנית עמוד או עמוד ייחודי או מסמך (PDF, Word וכד') בנפרד. לצורך כך, יש לשכפל את הגיליון "בדיקת נגישות לאינטרנט". בכל גיליון יש לציין את שם העמוד / מסמך ואת כתובתו (URL).
D11: הבדיקות יבוצעו ברמת נגישות AA - משמעות הדבר היא שיש לעמוד בכל הקריטריונים ברמה A וברמה AA (אלא אם נתקבל פטור מביצוע התאמה מסוימת בשל מגבלה טכנולוגית). חייב שקיבל פטור מהתאמות נגישות באינטרנט בשל נטל כבד מדי לפי תקנה 35 (ב)(2) יעמוד ברמת נגישות A בלבד.
D12: היה ביצוע התאמה מסוימת בלתי אפשרי בשל מגבלה טכנולוגיות, רשאי החייב לבקש פטור ממורשה לנגישות השירות, מביצוע התאמה זו, על סמך חוות דעת של איש מקצוע מתחום האינטרנט. במידה וניתן פטור כאמור, יש לצרפו לטופס זה.
D13: בוצעו בשירות אינטרנט התאמות נגישות לפי התקנות, יציין החייב במקום בולט לעין באתר כי בוצעו בו התאמות נגישות בעבור אנשים עם מוגבלות.
D15: על פי התקנות נגישות לשירות הטופס מבוסס על:
D16: Web Content Accessibility Guidelines (WCAG) 2.0
D17: רמות הנגישות מותאמות לפי תקן ישראלי 5568

Sheet סיכום ומקרא
A1: בדיקת נגישות תכני אינטרנט - א.נ. שילו בע"מ
A2: anshilo.com | לפי תקנות שוויון זכויות לאנשים עם מוגבלות (התאמות נגישות לשירות), התשע"ג-2013, סימן ג' תקנה 35
A3: תאריך הבדיקה: 30.07.2026
A5: מה המסמך הזה, ומה הוא איננו
A6: זו בדיקה עצמית מקדימה של קוד התבנית והגדרות החנות, שנועדה לשמש בסיס לבדיקה הרשמית. היא איננה חוות דעת של מורשה נגישות שירות, ואינה מהווה תחליף לה: תקנה 29 מחייבת שההצהרה וההתאמות ייערכו בהתייעצות עם מורשה נגישות שירות, והבדיקה התקופתית לפי תקנה 93(א) (טופס 9) מבוצעת על ידו. את הגיליונות שלהלן יש להעביר למורשה כנקודת פתיחה - הוא יאמת, ישלים את מה שסומן כטרם נבדק, ויחתום.
A8: מקרא עמודת "תוצאה"
A9: תקין | B9: נבדק, ונמצא עומד בקריטריון. ההערה בעמודה I מפרטת את הראיה - קובץ ושורה, מדידה, או בדיקה שבוצעה בדפדפן.
A10: לא תקין | B10: נבדק, ונמצא שאינו עומד בקריטריון. לא נותרו כאלה: ארבעה כשלי ניגודיות, כשל בסימון הפוקוס בשדה הכמות וכשל בעצירת התנועה בסרגל ההודעות נמצאו במהלך הבדיקה ותוקנו.
A11: לא רלוונטי | B11: הקריטריון אינו חל על העמוד - למשל קריטריוני אודיו ווידאו באתר שאין בו מדיה מבוססת זמן. ההערה מסבירה על סמך מה נקבע.
A12: (ריק) | B12: טרם נבדק. הקריטריון דורש בדיקה שלא ניתן לבצע מתוך הקוד: קורא מסך, מעבר מקלדת ידני, הגדלה ל-200%, מאמת HTML, או התבוננות בתמונות עצמן. ההערה אומרת בדיוק מה נבדק ומה נותר. אלה הפריטים שהמורשה צריך להשלים.
A14: סיכום לפי עמוד
A15: עמוד / מסמך | B15: תקין | C15: לא תקין | D15: לא רלוונטי | E15: טרם נבדק | F15: סה"כ | G15: הפריטים שטרם נבדקו
A16: עמוד הבית | B16: =COUNTIF('עמוד הבית'!$F$4:$F$45,"תקין") -> 25 | C16: =COUNTIF('עמוד הבית'!$F$4:$F$45,"לא תקין") -> 0 | D16: =COUNTIF('עמוד הבית'!$F$4:$F$45,"לא רלוונטי") -> 11 | E16: =COUNTBLANK('עמוד הבית'!$F$4:$F$45) -> 6 | F16: =SUM(B16:E16) -> 42 | G16: 1.3.2, 1.4.4, 1.4.5, 2.1.1, 2.4.3, 4.1.1
A17: עמוד קטגוריה / אוסף מוצרים | B17: =COUNTIF('עמוד קטגוריה'!$F$4:$F$45,"תקין") -> 25 | C17: =COUNTIF('עמוד קטגוריה'!$F$4:$F$45,"לא תקין") -> 0 | D17: =COUNTIF('עמוד קטגוריה'!$F$4:$F$45,"לא רלוונטי") -> 11 | E17: =COUNTBLANK('עמוד קטגוריה'!$F$4:$F$45) -> 6 | F17: =SUM(B17:E17) -> 42 | G17: 1.3.2, 1.4.4, 1.4.5, 2.1.1, 2.4.3, 4.1.1
A18: עמוד מוצר | B18: =COUNTIF('עמוד מוצר'!$F$4:$F$45,"תקין") -> 25 | C18: =COUNTIF('עמוד מוצר'!$F$4:$F$45,"לא תקין") -> 0 | D18: =COUNTIF('עמוד מוצר'!$F$4:$F$45,"לא רלוונטי") -> 11 | E18: =COUNTBLANK('עמוד מוצר'!$F$4:$F$45) -> 6 | F18: =SUM(B18:E18) -> 42 | G18: 1.3.2, 1.4.4, 1.4.5, 2.1.1, 2.4.3, 4.1.1
A19: עגלת קניות | B19: =COUNTIF('עגלת קניות'!$F$4:$F$45,"תקין") -> 26 | C19: =COUNTIF('עגלת קניות'!$F$4:$F$45,"לא תקין") -> 0 | D19: =COUNTIF('עגלת קניות'!$F$4:$F$45,"לא רלוונטי") -> 11 | E19: =COUNTBLANK('עגלת קניות'!$F$4:$F$45) -> 5 | F19: =SUM(B19:E19) -> 42 | G19: 1.3.2, 1.4.4, 2.1.1, 2.4.3, 4.1.1
A20: תוצאות חיפוש | B20: =COUNTIF('תוצאות חיפוש'!$F$4:$F$45,"תקין") -> 25 | C20: =COUNTIF('תוצאות חיפוש'!$F$4:$F$45,"לא תקין") -> 0 | D20: =COUNTIF('תוצאות חיפוש'!$F$4:$F$45,"לא רלוונטי") -> 11 | E20: =COUNTBLANK('תוצאות חיפוש'!$F$4:$F$45) -> 6 | F20: =SUM(B20:E20) -> 42 | G20: 1.3.2, 1.4.4, 1.4.5, 2.1.1, 2.4.3, 4.1.1
A21: עמוד תוכן (מי אנחנו, שאלות ותשובות) | B21: =COUNTIF('עמוד תוכן'!$F$4:$F$45,"תקין") -> 25 | C21: =COUNTIF('עמוד תוכן'!$F$4:$F$45,"לא תקין") -> 0 | D21: =COUNTIF('עמוד תוכן'!$F$4:$F$45,"לא רלוונטי") -> 11 | E21: =COUNTBLANK('עמוד תוכן'!$F$4:$F$45) -> 6 | F21: =SUM(B21:E21) -> 42 | G21: 1.3.2, 1.4.4, 1.4.5, 2.1.1, 2.4.3, 4.1.1
A22: עמודי מדיניות, תקנון והצהרת נגישות | B22: =COUNTIF('עמודים משפטיים'!$F$4:$F$45,"תקין") -> 25 | C22: =COUNTIF('עמודים משפטיים'!$F$4:$F$45,"לא תקין") -> 0 | D22: =COUNTIF('עמודים משפטיים'!$F$4:$F$45,"לא רלוונטי") -> 12 | E22: =COUNTBLANK('עמודים משפטיים'!$F$4:$F$45) -> 5 | F22: =SUM(B22:E22) -> 42 | G22: 1.3.2, 1.4.4, 2.1.1, 2.4.3, 4.1.1
A23: עמוד יצירת קשר | B23: =COUNTIF('יצירת קשר'!$F$4:$F$45,"תקין") -> 26 | C23: =COUNTIF('יצירת קשר'!$F$4:$F$45,"לא תקין") -> 0 | D23: =COUNTIF('יצירת קשר'!$F$4:$F$45,"לא רלוונטי") -> 9 | E23: =COUNTBLANK('יצירת קשר'!$F$4:$F$45) -> 7 | F23: =SUM(B23:E23) -> 42 | G23: 1.1.1, 1.3.2, 1.4.4, 1.4.5, 2.1.1, 2.4.3, 4.1.1
A24: התחברות, הרשמה וחשבון לקוח | B24: =COUNTIF('חשבון לקוח'!$F$4:$F$45,"תקין") -> 26 | C24: =COUNTIF('חשבון לקוח'!$F$4:$F$45,"לא תקין") -> 0 | D24: =COUNTIF('חשבון לקוח'!$F$4:$F$45,"לא רלוונטי") -> 10 | E24: =COUNTBLANK('חשבון לקוח'!$F$4:$F$45) -> 6 | F24: =SUM(B24:E24) -> 42 | G24: 1.1.1, 1.3.2, 1.4.4, 2.1.1, 2.4.3, 4.1.1
A25: בלוג וכתבת בלוג | B25: =COUNTIF('בלוג וכתבה'!$F$4:$F$45,"תקין") -> 25 | C25: =COUNTIF('בלוג וכתבה'!$F$4:$F$45,"לא תקין") -> 0 | D25: =COUNTIF('בלוג וכתבה'!$F$4:$F$45,"לא רלוונטי") -> 10 | E25: =COUNTBLANK('בלוג וכתבה'!$F$4:$F$45) -> 7 | F25: =SUM(B25:E25) -> 42 | G25: 1.1.1, 1.3.2, 1.4.4, 1.4.5, 2.1.1, 2.4.3, 4.1.1
A26: עמוד שגיאה 404 | B26: =COUNTIF('שגיאה 404'!$F$4:$F$45,"תקין") -> 25 | C26: =COUNTIF('שגיאה 404'!$F$4:$F$45,"לא תקין") -> 0 | D26: =COUNTIF('שגיאה 404'!$F$4:$F$45,"לא רלוונטי") -> 11 | E26: =COUNTBLANK('שגיאה 404'!$F$4:$F$45) -> 6 | F26: =SUM(B26:E26) -> 42 | G26: 1.3.2, 1.4.4, 1.4.5, 2.1.1, 2.4.3, 4.1.1
A27: סה"כ | B27: =SUM(B16:B26) -> 278 | C27: =SUM(C16:C26) -> 0 | D27: =SUM(D16:D26) -> 118 | E27: =SUM(E16:E26) -> 66 | F27: =SUM(F16:F26) -> 462
A29: מה תוקן במהלך הבדיקה הזו
A30: 1.4.3 - ניגודיות | B30: צבע ההדגשה על גבי הרקע הוורוד הבהיר נמדד 4.47:1 ו-4.06:1, מתחת ל-4.5:1 הנדרש. הוחלף בגוון כהה יותר של אותו הגוון (6.07:1 ו-5.52:1) בחמש קומפוננטות. נמדדו 36 שילובי צבע; כל השאר עומדים.
A31: 2.4.7 - פוקוס נראה לעין | B31: שדה הכמות ביטל את מסגרת הפוקוס ולא החזיר דבר במקומה, כך שמעבר מקלדת אליו - בעמוד המוצר, בעגלה, במגירת העגלה ובהזמנה מהירה - לא הראה שום סימן. הוחזרה מסגרת 2px, במרווח שלילי כדי שהמעטפת לא תחתוך אותה.
A32: 2.2.2 - הפסקה, עצירה, הסתרה | B32: לחצן "עצירת אנימציות ותנועה" שבתפריט הנגישות לא עצר את סרגל ההודעות: גיליון סגנון אינו יכול לעצור טיימר. הסרגל נגזר כיום מבחירת המבקר, מהגדרת הסוחר ומהגדרת מערכת ההפעלה, ונעצר ברגע הלחיצה. אותה סיבה גם מנעה מהלחצן לעצור את אנימציות פתיחת האקורדיון, וגם זה תוקן.
A34: מה נדרש כדי לסגור את הבדיקה
A35: • בדיקת קורא מסך על כל תבנית עמוד - הטופס מחייב זאת מפורשות בקריטריון 1.3.2.
A36: • מעבר מקלדת ידני מלא בכל עמוד, כולל מגירת העגלה, מגירת הסינון, גלריית המוצר וההזמנה המהירה (קריטריונים 2.1.1 ו-2.4.3).
A37: • הגדלת התצוגה ל-200% בכל עמוד ואימות שלא נאבד תוכן או פונקציונליות (1.4.4).
A38: • הרצת מאמת HTML של W3C על העמודים כפי שהם מורכבים בפועל (4.1.1).
A39: • התבוננות בתמונות הבאנר והאריחים שהועלו, ואימות שאין בהן טקסט "צרוב" (1.4.5).
A40: • אימות מול Shopify של נגישות מנגנון ההגנה מפני ספאם בטפסים, ושל קיום חלופה נגישה (1.1.1 CAPTCHA).
A41: • חוות דעת של מורשה נגישות שירות, כנדרש בתקנה 29, וחתימתו על טופס זה.
A43: רכז הנגישות: דביר ארליכמן | טלפון 058-455-4333 | דוא"ל info@anshilo.com

Sheet עמוד הבית
A1: שם העמוד / מסמך: | B1: עמוד הבית | C1: כתובת העמוד / מסמך (URL): | D1: https://anshilo.com/
I2: מקרא: תא ריק בעמודת "תוצאה" משמעו שהקריטריון טרם נבדק, והסיבה מופיעה בהערה. ראו גיליון "סיכום ומקרא".
A3: הנחיה | B3: מס קריטריון | C3: קריטריון בדיקה | D3: תאור הקריטריון | E3: רמה נדרשת בישראל | F3: תוצאה (תקין / לא תקין / לא רלוונטי) | G3: טכניקות לביצוע (באנגלית) (בSilver light, PDF, Flash, HTML) | H3: הסבר על הקריטריון (באנגלית) | I3: הערות הבדיקה, והראיה שעליה היא מבוססת
A4: הנחיה 1.1 חלופה טקסטואלית: יש לספק חלופות טקסטואליות עבור תכנים שאינם טקסטואליים, כך שניתן יהיה להמירן לצורות אחרות להן זקוקים אנשים, כמו אותיות גדולות, ברייל, דיבור, סמלים או שפה פשוטה יותר. | B4: 1.1.1 | C4: תכנים שאינם טקסטואליים | D4: א. לתמונות יש טקסט אלטרנטיבי באמצעות המאפיין alt, המתאר את מהות התמונה (כולל תמונות של כפתורים בטפסים ותמונות של hot spots ב image map.) ב. לתמונות המהוות קישור יש טקסט החלופי מגדיר את מטרת הקישור תמונות ג. לתמונות שאינן מעבירות מידע, כלומר משמשות לדקורציה בלבד, או תמונות שאינן מהוות קישור הכוללת מידע שקיים כבר בטקסט, יש טקסט חלופי ריק ""=alt או שהן מיושמות כרקע ב CSS ד. חלופות שווה ערך לתמונות מורכבות מסופקות בהקשר או בדף הנפרד (צמוד ו / או הפניה באמצעות longdesc). | E4: A | F4: תקין | G4: טכניקות לביצוע קריטריון 1.1.1 | H4: הסבר על קריטריון 1.1.1 | I4: נסרקו כל תבניות התבנית: 39 תגי img, לכולם מאפיין alt. בתמונות מוצר, אוסף וכתבה ה-alt נגזר מה-alt של המדיה, ובהיעדרו משם הפריט (snippets/product-card.liquid:100, snippets/product-media-gallery.liquid:134). 11 תמונות נושאות alt="" ביודעין: הן תמונות קישוט שלצדן מופיעה כבר כותרת טקסט גלויה, או שהן בתוך לחצן הנושא aria-label בעצמו (snippets/product-media-gallery.liquid:305), כך שקורא המסך אינו קורא אותן פעמיים. לתמונות המהוות קישור - הקישור עצמו נושא את שם הפריט. אין באתר תמונות מורכבות (תרשימים, גרפים) הדורשות תיאור ארוך. הערה: התאמת נוסח ה-alt לכל אחת מכ-1,900 תמונות המוצר היא שיקול תוכן ואינה ניתנת לאימות מתוך הקוד.
A5: הנחיה 1.1 חלופה טקסטואלית | B5: 1.1.1 | C5: תכנים שאינם טקסטואליים | D5: מולטימדיה משובצת - embedded - מזוהה באמצעות טקסט חלופי | E5: A | F5: לא רלוונטי | G5: טכניקות לביצוע קריטריון 1.1.1 | H5: הסבר על קריטריון 1.1.1 | I5: לא נמצאה באתר מדיה מבוססת זמן. בתבנית אין נגן אודיו או וידאו, ובדגימה של 30 המוצרים שעודכנו לאחרונה כל פריטי המדיה הם מסוג IMAGE (נשלף מ-Shopify Admin API, שדה mediaContentType). אם יתווסף וידאו או אודיו לאתר - יש לבדוק שורה זו מחדש.
A6: הנחיה 1.1 חלופה טקסטואלית | B6: 1.1.1 | C6: תכנים שאינם טקסטואליים | D6: למדיה מבוססת זמן (וידאו, אודיו, אנימציה), למבחן (שחלופה מלאה תפגע באפקטיביות שלו) ולתוכן שאינו טקסטואלי המהווה חוויה חושית - יש חלופה טקסטואלית, שלכל הפחות, מזהה אותו ומתארת את תוכנו. | E6: A | F6: לא רלוונטי | G6: טכניקות לביצוע קריטריון 1.1.1 | H6: הסבר על קריטריון 1.1.1 | I6: לא נמצאה באתר מדיה מבוססת זמן. בתבנית אין נגן אודיו או וידאו, ובדגימה של 30 המוצרים שעודכנו לאחרונה כל פריטי המדיה הם מסוג IMAGE (נשלף מ-Shopify Admin API, שדה mediaContentType). אם יתווסף וידאו או אודיו לאתר - יש לבדוק שורה זו מחדש. אין באתר גם מבחן או תוכן המהווה חוויה חושית.
A7: הנחיה 1.1 חלופה טקסטואלית | B7: 1.1.1 | C7: תכנים שאינם טקסטואליים | D7: קיימת CHAPTCHA נגישה או חלופה ל CHAPTCHA - אם מטרתו של תוכן שאינו טקסט לוודא שהניגש לתוכן הוא אדם ולא מחשב, יש לספק חלופה טקסטואלית שתזהה את התוכן ותתאר את תכליתו, בנוסף לצורות חלופיות של CAPTCHA המכוונות לתפיסה בחושים אחרים, ומתאימות למוגבלויות שונות. | E7: A | F7: לא רלוונטי | G7: טכניקות לביצוע קריטריון 1.1.1 | H7: הסבר על קריטריון 1.1.1 | I7: אין בעמוד זה מנגנון CAPTCHA.
A8: הנחיה 1.2 מדיה מבוססת-זמן: יש להמציא חלופות עבור מדיה מבוססת-זמן. | B8: 1.2.1 | C8: אודיו-בלבד ווידאו-בלבד (הקלטה מראש) | D8: לאודיו בלבד (מוקלט מראש למשל web cast) - יש תסריט המכיל את כל המידע האודיטורי הרלוונטי להבנת התוכן (הנ"ל יסופק במועד מוקדם ככל האפשר). | E8: AA | F8: לא רלוונטי | G8: טכניקות לביצוע קריטריון 1.2.1 | H8: הסבר על קריטריון 1.2.1 | I8: לא נמצאה באתר מדיה מבוססת זמן. בתבנית אין נגן אודיו או וידאו, ובדגימה של 30 המוצרים שעודכנו לאחרונה כל פריטי המדיה הם מסוג IMAGE (נשלף מ-Shopify Admin API, שדה mediaContentType). אם יתווסף וידאו או אודיו לאתר - יש לבדוק שורה זו מחדש.
A9: הנחיה 1.2 מדיה מבוססת-זמן | B9: 1.2.1 | C9: אודיו-בלבד ווידאו-בלבד (הקלטה מראש) | D9: לוידיאו בלבד (מוקלט מראש) - יש תסריט טקסטואלי או ערוץ אודיו המתאר את הערוץ הוויזואלי. (הנ"ל יסופק במועד מוקדם ככל האפשר). | E9: AA | F9: לא רלוונטי | G9: טכניקות לביצוע קריטריון 1.2.1 | H9: הסבר על קריטריון 1.2.1 | I9: לא נמצאה באתר מדיה מבוססת זמן. בתבנית אין נגן אודיו או וידאו, ובדגימה של 30 המוצרים שעודכנו לאחרונה כל פריטי המדיה הם מסוג IMAGE (נשלף מ-Shopify Admin API, שדה mediaContentType). אם יתווסף וידאו או אודיו לאתר - יש לבדוק שורה זו מחדש.
A10: הנחיה 1.2 מדיה מבוססת-זמן | B10: 1.2.2 | C10: כתוביות | D10: בוידאו הכולל סאונד (קבצי וידאו, סרטוני YouTube וכדומה) יופיעו כתוביות מסונכרנות וחלופה טקסטואלית. (הנ"ל יסופק במועד מוקדם ככל האפשר). | E10: AA | F10: לא רלוונטי | G10: טכניקות לביצוע קריטריון 1.2.2 | H10: הסבר על קריטריון 1.2.2 | I10: לא נמצאה באתר מדיה מבוססת זמן. בתבנית אין נגן אודיו או וידאו, ובדגימה של 30 המוצרים שעודכנו לאחרונה כל פריטי המדיה הם מסוג IMAGE (נשלף מ-Shopify Admin API, שדה mediaContentType). אם יתווסף וידאו או אודיו לאתר - יש לבדוק שורה זו מחדש.
A11: הנחיה 1.2 מדיה מבוססת-זמן | B11: 1.2.3 | C11: תיאורי אודיו או חלופה טקסטואלית למדיה (מוקלטת מראש) | D11: תיאורי אודיו - טקסט (תסריט הכולל תיאורי אודיו) או תיאורי אודיו מלווים את הסרט הוידיאו ומתארים את כל ההתרחשויות הויזואליות שלא ניתן להם תיאור באודיו בסרט עצמו. (לדוגמא להוסיף את המילים "הקהל צוחק" לכתוביות). (הנ"ל יסופק במועד מוקדם ככל האפשר). | E11: AA | F11: לא רלוונטי | G11: טכניקות לביצוע קריטריון 1.2.3 | H11: הסבר על קריטריון 1.2.3 | I11: לא נמצאה באתר מדיה מבוססת זמן. בתבנית אין נגן אודיו או וידאו, ובדגימה של 30 המוצרים שעודכנו לאחרונה כל פריטי המדיה הם מסוג IMAGE (נשלף מ-Shopify Admin API, שדה mediaContentType). אם יתווסף וידאו או אודיו לאתר - יש לבדוק שורה זו מחדש.
A12: הנחיה 1.2 מדיה מבוססת-זמן | B12: 1.2.5 | C12: תיאורי אודיו למדיה (מוקלטת מראש) | D12: תיאורי אודיו מלווים את הסרט הוידיאו ומתארים את כל ההתרחשויות הויזואליות שלא ניתן להם תיאור באודיו בסרט עצמו. (הנ"ל יסופק במועד מוקדם ככל האפשר). | E12: AA | F12: לא רלוונטי | G12: טכניקות לביצוע קריטריון 1.2.5 | H12: הסבר על קריטריון 1.2.5 | I12: לא נמצאה באתר מדיה מבוססת זמן. בתבנית אין נגן אודיו או וידאו, ובדגימה של 30 המוצרים שעודכנו לאחרונה כל פריטי המדיה הם מסוג IMAGE (נשלף מ-Shopify Admin API, שדה mediaContentType). אם יתווסף וידאו או אודיו לאתר - יש לבדוק שורה זו מחדש.
A13: הנחיה 1.3 ניתן להתאמה: יש לבנות תכנים הניתנים להצגה בדרכים שונות (למשל מתווה פשוט יותר) ללא איבוד מידע או מבנה. | B13: 1.3.1 | C13: מידע וקשרים - מידע, מבנה, והקשרים הסמנטיים בין חלקי העמוד המועברים באמצעים ויזואליים (כגון גודל פונט, מסגרות, רקעים וכד') ניתנים להבנה גם באמצעות הקוד: | D13: כתיבת קוד סמנטי: א. כותרות: שימוש <h1> to <h6> לזהות כותרות ב. רשימות: שימוש <ul>, <ol>, and <dl>לרשימות או קבוצות של קישורים (כולל תפריטים) ג. טקסטים מיוחדים: שימוש בסימון סמנטי כדי לסמן טקסט מודגש או מיוחד (לדוגמא <strong>, <code>, <abbr>, <block quote>) ד. טבלאות: שימוש בסימון טבלה להצגת מידע טבלאי (TH לתאי כותרת או scope attribute), וכן שימוש ב caption elements כדי לשייך כותרת טבלת נתונים עם טבלת נתונים, וב Summary element בהתאם לצורך. ה. טפסים: שימוש label elements לשייך תוויות טקסט עם פקדי טופס. מתן תיאור עבור קבוצות של פקדי טופס באמצעות קבוצת שדות וlegend elements. ו. אזורים בעמוד: אזורים בעמוד (תפריט ניווט, איזור ראשי וכד') מוגדרים באמצעות landmarks (רצוי) | E13: A | F13: תקין | G13: טכניקות לביצוע קריטריון 1.3.1 | H13: הסבר על קריטריון 1.3.1 | I13: קוד סמנטי מלא: main[role="main"] (layout/theme.liquid:291), header (sections/header.liquid:71), footer[role="contentinfo"] (sections/footer.liquid:51), nav עם aria-label לכל אזור ניווט, form[role="search"] לחיפוש. רשימות וקבוצות קישורים מסומנות ב-ul/ol. טבלאות: נסרקו כל הטבלאות בתבנית - לכולן תאי כותרת th עם scope. טפסים: נסרקו כל הפקדים - לא נמצא פקד ללא תווית (label, aria-label או aria-labelledby); בורר הווריאנטים מקובץ ב-fieldset עם legend (snippets/product-variant-picker.liquid:93). לא נמצא סימון תצוגתי במקום סמנטי (font, center, big, tt, bgcolor, align).
A14: הנחיה 1.3 ניתן להתאמה | B14: 1.3.1 | C14: מידע וקשרים | D14: קיימת הפרדה מלאה בין תוכן לתצוגה על ידי שימוש ב CSS | E14: A | F14: תקין | G14: טכניקות לביצוע קריטריון 1.3.1 | H14: הסבר על קריטריון 1.3.1 | I14: הפרדה מלאה בין תוכן לתצוגה: כל העיצוב יושב בגיליונות סגנון חיצוניים. שימושי המאפיין style= שנותרו בתבנית מעבירים ערכי custom properties בלבד (למשל --nav-thumb-size), ואינם עיצוב בתוך התגית. לא נמצאו תגיות תצוגה (font, center, big, tt) ולא פריסה מבוססת טבלאות.
A15: הנחיה 1.3 ניתן להתאמה | B15: 1.3.2 | C15: רצף בעל משמעות | D15: כאשר הסדר שבו מוצג תוכן משפיע על המשמעות של התוכן, הרצף יקבע בקוד (שימו לב לסדר המידע בקוד יש השפעה על האופן בו הוא מוקרא לעיוורים העושים שימוש בקוראה מסך לכן חובה לבצע את הבדיקה באמצעות קורא מסך ולוודא שסדר ההקראה לוגי) | E15: A | G15: טכניקות לביצוע קריטריון 1.3.2 | H15: הסבר על קריטריון 1.3.2 | I15: הטופס מחייב לבצע קריטריון זה בבדיקת קורא מסך, וזו לא בוצעה - ולכן השורה נותרת ריקה. מה שכן נבדק: סדר ה-DOM תואם את סדר ההצגה, ולא נמצא שינוי סדר באמצעות CSS.
A16: הנחיה 1.3 ניתן להתאמה | B16: 1.3.3 | C16: מאפייני חישה | D16: הוראות אינן מסתמכות על צבע, צורה, או מיקום על המסך (לדוגמא, "לחץ על הכפתור המרובע כדי להמשיך", או "קרא את הוראות בצבע כחול") הוראות אינן מסתמכות על סאונד (לדוגמא, המתן להישמע צפצוף כדי לעבוד לשלב הבא). | E16: A | F16: תקין | G16: טכניקות לביצוע קריטריון 1.3.3 | H16: הסבר על קריטריון 1.3.3 | I16: נסרקו כל מחרוזות הממשק בקובץ locales/he.default.json: אין באתר הוראה המסתמכת על צבע, על צורה, על מיקום על המסך או על צליל. אין הוראות מסוג "לחץ על הכפתור המרובע" או "קרא את הכתוב באדום".
A17: הנחיה 1.4 בר-הבחנה | B17: 1.4.1 | C17: שימוש בצבע | D17: א. צבע אינו אמצעי יחידי - צבע אינו משמש כאמצעי החזותי היחיד להעברת מידע, סימון פעולה, בקשת תגובה, או הבחנה בפרט חזותי. ב. צבע אינו המבחין היחידי לסימון קישורים. אלא אם כן הבדלי הצבע בין הקישור לטקסט רגיל הוא 1:3 ועיצוב קישור משתנה במרכיב נוסף מלבד צבע on mouse over ו on focus (לדוגמא underline) . | E17: A | F17: תקין | G17: טכניקות לביצוע קריטריון 1.4.1 | H17: הסבר על קריטריון 1.4.1 | I17: מידע אינו מועבר בצבע בלבד: תגי המצב נושאים טקסט ("מבצע", "אזל מהמלאי", "חדש"), וזמינות המוצר מנוסחת במילים ולא בנקודה צבעונית. קישורים: הפרש הניגודיות בין צבע הקישור (#D81E29) לטקסט הגוף (#16202F) נמדד 3.23:1 - מעל ה-3:1 שהקריטריון מתיר - ובנוסף הקישור נבדל במשקל גופן 600, מקבל קו תחתון בריחוף עכבר ומסגרת פוקוס בקבלת פוקוס (assets/base.css:91, 97, 105), כנדרש. קישורים בתוך גוף טקסט (.rte a) נושאים קו תחתון כברירת מחדל של הדפדפן. הערה לשיפור: קישור המונח בתוך פסקה בצבע המשני (#5B6779) נבדל ממנה ב-1.13:1 בלבד ומסתמך שם על משקל הגופן ועל ה-hover/focus בלבד; קו תחתון קבוע לכל הקישורים יסיר את התלות הזו.
A18: הנחיה 1.4 בר-הבחנה | B18: 1.4.2 | C18: שליטה באודיו | D18: שליטה באודיו - קיים מנגנון עצירה או הפסקה, או לשליטה בעוצמה של אודיו המנגן אוטומטית בדף במשך למעלה מ 3 שניות. | E18: A | F18: לא רלוונטי | G18: טכניקות לביצוע קריטריון 1.4.2 | H18: הסבר על קריטריון 1.4.2 | I18: אין בעמוד אודיו המתנגן אוטומטית.
A19: הנחיה 1.4 בר-הבחנה | B19: 1.4.3 | C19: קונטרסט | D19: קונטרסט - עבור כל הטקסטים בעמוד - יחס-קונטרסט של לפחות 4.5:1 בטקסט רגיל. בטקסט גדול (over 18 point or 14 point bold) יחס של לפחות 3:1 (למעט: לוגו, טקסטים המשמשים כרקע לתמונה, טקסטים שלא נראים לאף אחד) אם לא ניתן לעמוד בהנחיה זו מותר על פי התקנות לעשות שימוש בסט צבעים נוסף לאתר העומד בהנחיה. | E19: AA | F19: תקין | G19: טכניקות לביצוע קריטריון 1.4.3 | H19: הסבר על קריטריון 1.4.3 | I19: נמדדו 36 שילובי הצבע שהתבנית מייצרת בפועל - לא רק ההגדרות הגולמיות, אלא גם הגוונים שהפריסה מחשבת במסננים color_mix ו-color_lighten. ארבעה שילובים נכשלו ותוקנו במסגרת בדיקה זו: צבע ההדגשה על גבי הרקע הוורוד הבהיר נמדד 4.47:1 ו-4.06:1, מתחת ל-4.5:1 הנדרש, והוחלף בגוון כהה יותר של אותו הגוון (6.07:1 ו-5.52:1) בקומפוננטות .btn--quiet, .badge--soft, .price__save, ווריאנט נבחר ותג "נבחרו" בסינון. כל שאר השילובים נמדדו 4.69:1 ומעלה, וטקסט הגוף 16.38:1. גבולות שאינם נושאי מידע ואייקונים נבדקו בנפרד מול דרישת ה-3:1 וחורגים ממנה לטובה. באזור התמונה הראשי בעמוד הבית, שבו טקסט מונח על צילום ולכן זהו המקרה המורכב ביותר, נמדדה ניגודיות של 6.7:1 לכל הפחות - הבדיקה בוצעה מול תחליף בהיר מאוד ותחליף כהה מאוד שנבנו במיוחד כדי לתחום את טווח הצילומים האפשרי.
A20: הנחיה 1.4 בר-הבחנה | B20: 1.4.4 | C20: הגדלת טקסט | D20: הגדלת טקסט - כאשר מגדילים את הטקסט ב 200% (פי 2) אין פגיעה במידע ובפונקציונאליות של העמוד. | E20: AA | G20: טכניקות לביצוע קריטריון 1.4.4 | H20: הסבר על קריטריון 1.4.4 | I20: דרושה בדיקה ידנית של הגדלה ל-200% בעמוד עצמו, וזו לא בוצעה - ולכן השורה נותרת ריקה. מה שכן נבדק: הטיפוגרפיה כולה מבוססת יחידות rem ולכן נגררת עם שינוי גודל הגופן, וכך גם עובדים צעדי הגדלת הטקסט שבתפריט הנגישות, המשנים את גודל הגופן של השורש (assets/accessibility.css:135); הערך היחיד בכל גיליונות הסגנון שהוגדר ב-px הוא תווית בתוך ציור SVG בעל viewBox, הנגררת עם הציור ואינה טקסט תוכן; ולא נמצא מכל טקסט בעל גובה קבוע שעלול לחתוך תוכן בהגדלה.
A21: הנחיה 1.4 בר-הבחנה | B21: 1.4.5 | C21: תמונות של טקסט | D21: אם טכנולוגית ניתן להשיג את אותה תצוגה ויזואלית באמצעות טקסט חי (למשל טקסט חי על תמונת רקע) אין להשתמש בטקסט של תמונה. פרט ל: אם קיימת טכניקה בה התמונה של טקסט יכולה להיות מותאמת אישית מבחינה ויזואלית לדרישות של המשתמש; או שהתמונה היא חיונית: הצגה מסוימת של טקסט בתמונה היא חיונית למידע (הערה - לוגו או brand נחשבים לחיוניים). | E21: AA | G21: טכניקות לביצוע קריטריון 1.4.5 | H21: הסבר על קריטריון 1.4.5 | I21: דרושה בדיקה חזותית של התמונות שהועלו לחנות, וזו לא בוצעה: סביבת הבדיקה חסומה מהגעה לתמונות עצמן - ולכן השורה נותרת ריקה. מה שכן ידוע: התבנית מציגה כותרות, כפתורים ומחירים כטקסט חי ולא כתמונה. יש לוודא שבתמונות הבאנר והאריחים אין טקסט "צרוב" שאפשר היה להציג כטקסט חי. הלוגו פטור על פי הקריטריון.
A22: הנחיה 2.1 מקלדת נגישה: יש לאפשר תפקוד מלא ממקלדת. | B22: 2.1.1 | C22: מקלדת | D22: א. כל הפעולות באתר ניתנות לביצוע באמצעות מקלדת לחיצה על מקש tab) ב. מעבר הפוקוס לוגי - מעבר לוגי אינטואיטיבי ומותאם למבנה המסך בין קישורים, פקדים וכדומה. ג. רכיבים שאינם HTML מאפשרים שימוש מלא במקלדת המותאם להתנהגות רכיבי html. ד. כאשר רכיב בדף מקבל פוקוס הדבר לא מעורר שינוי משמעותי בדף (פתיחת דף נוסף, הופעת popup, העברת הפוקוס לרכיב אחר וכדומה) | E22: A | G22: טכניקות לביצוע קריטריון 2.1.1 | H22: הסבר על קריטריון 2.1.1 | I22: דרוש מעבר מקלדת ידני מלא על העמוד, והוא לא בוצע במלואו - ולכן השורה נותרת ריקה. מה שכן נבדק: אין tabindex חיובי בשום מקום בתבנית; אין מטפל אירועים על אלמנט לא אינטראקטיבי (div/span עם onclick); כל הפקדים הם רכיבי HTML מקוריים - button, a, input, select, details/summary - ולא חיקויים; אין role="button" על אלמנט שאינו לחצן. נבדק בפועל בדפדפן: לוח החיפוש (פתיחה, הקלדה, בחירה, Escape, לחיצה בחוץ), רכיבי האקורדיון של תיאור המוצר ושאלות ומשלוחים, סרגל ההודעות וכפתור ההוספה לעגלה בכרטיס המוצר. טרם נבדקו ידנית: מגירת העגלה, מגירת הסינון, גלריית המוצר, ההזמנה המהירה וטפסי החשבון.
A23: הנחיה 2.1 מקלדת נגישה | B23: 2.1.2 | C23: מלכודות מקלדת | D23: הדף אינו כולל "מלכודות מקלדת" (אלמנטים שניתן להגיע אליהם באמצעות המקלדת אך לא ניתן לנווט מהם הלאה) | E23: A | F23: תקין | G23: טכניקות לביצוע קריטריון 2.1.2 | H23: הסבר על קריטריון 2.1.2 | I23: המגירות (תפריט, עגלה, סינון) מלכידות פוקוס בכוונה, כמצופה מחלון מודאלי, אך המלכודת מסתובבת בין הרכיבים ואינה חוסמת יציאה: Escape סוגר את המגירה והפוקוס חוזר ללחצן שפתח אותה (assets/global.js:54-81, 126). נבדק בדפדפן עבור לוח החיפוש ורכיבי האקורדיון. לא נמצא בתבנית רכיב שניתן להיכנס אליו במקלדת ולא לצאת ממנו.
A24: הנחיה 2.2 זמן מספיק: יש לתת למשתמשים מספיק זמן לקרוא ולהשתמש בתכנים. | B24: 2.2.1 | C24: כוונון זמן | D24: בכל מצב בו יש הגבלת זמן לקריאה, תגובה או פעולה (כולל time out), למשתמש ניתנת אפשרות לבטל, להאריך, או להתאים לעצמו את הגבלת הזמן. (למעט מקרים בהם הגבלת הזמן היא מעל 20 שעות). | E24: A | F24: לא רלוונטי | G24: טכניקות לביצוע קריטריון 2.2.1 | H24: הסבר על קריטריון 2.2.1 | I24: אין בעמוד הגבלת זמן לקריאה, לתגובה או להשלמת פעולה, ואין time out המוגדר בתבנית.
A25: הנחיה 2.2 זמן מספיק | B25: 2.2.2 | C25: הפסקה, עצירה, הסתרה | D25: א. ניתן להפסיק, לעצור או להסתיר מידע מהבהב, נע או נגלל (שמופיע במשך יותר מ 5 שניות) ב.יש לקבוע מנגנון שיאפשר למשתמש לעצור, להפסיק או להסתיר מידע המתעדכן באופן אוטומטי, או שיאפשר שליטה בתדירות העדכון, אם המידע (1) מופיע באופן אוטומטי, (2) מוצג במקביל לתוכן אחר; למעט מקרים שבהם העדכון האוטומטי מהותי לפעולה. | E25: A | F25: תקין | G25: טכניקות לביצוע קריטריון 2.2.2 | H25: הסבר על קריטריון 2.2.2 | I25: סרגל ההודעות שבראש כל עמוד מחליף את תוכנו על טיימר, ולכן הקריטריון רלוונטי בכל עמוד. עד לתיקון שבוצע בבדיקה זו לא היה ניתן לעצור אותו: גיליון סגנון אינו יכול לעצור setInterval, ולכן לחצן "עצירת אנימציות ותנועה באתר" שבתפריט הנגישות לא הגיע אליו כלל, וגם הגדרת מערכת ההפעלה נבדקה פעם אחת בלבד בעת טעינת העמוד. כיום הטיימר נגזר משלושה מקורות - בחירת המבקר בתפריט הנגישות, הגדרת הסוחר בתבנית והגדרת מערכת ההפעלה - ונבדק מחדש בכל הפעלה, ואירוע shilo:motion עוצר סבב שכבר בתנועה ברגע הלחיצה ומחזיר את הסרגל לשקופית הראשונה. נבדק ב-Chromium: 3 חילופי שקופית ב-1.1 שניות כשהתנועה מותרת, ו-0 חילופים לאחר הלחיצה, על פני יותר משלושה מרווחי טיימר. בנוסף הסרגל נעצר בריחוף עכבר ובקבלת פוקוס. אין בעמוד תוכן נגלל, מהבהב או מתעדכן אוטומטית אחר.
A26: הנחיה 2.3 התקפים: אין לעצב תכנים באופן הידוע כגורם להתקפים. | B26: 2.3.1 | C26: הבהוב וריצוד | D26: אין הבהוב או ריצוד על במסך בקצב של יותר משלוש פעמים בשנייה או general flash and red flash thresholds. | E26: A | F26: תקין | G26: טכניקות לביצוע קריטריון 2.3.1 | H26: הסבר על קריטריון 2.3.1 | I26: אין באתר תוכן מהבהב או מרצד. אין אנימציה הפועלת בקצב העולה על שלוש פעמים בשנייה, ואין הבזקים בשטח או בעוצמה החורגים מ-general flash ו-red flash thresholds.
A27: הנחיה 2.4 ניתן לניווט: יש לספק דרכים כדי לעזור למשתמשים לנווט, לאתר תכנים, ולקבוע את מקום הימצא. | B27: 2.4.1 | C27: עקיפת בלוקים | D27: קיים מנגנון לעקיפת בלוקים (יחידות קבועות שחוזרות על עצמן במספר עמודים כגון תפריטים, באנרים וכד'). המנגנון תומך בניווט ישיר לתוכן העמוד. | E27: A | F27: תקין | G27: טכניקות לביצוע קריטריון 2.4.1 | H27: הסבר על קריטריון 2.4.1 | I27: קיים קישור "דילוג לתוכן", ראשון בסדר המקלדת, מוסתר עד לקבלת פוקוס ומוביל ישירות ל-#MainContent (layout/theme.liquid:278, 291). בנוסף אזורי הדף מסומנים ב-landmarks, המאפשרים לקורא מסך לדלג בין בלוקים ישירות.
A28: הנחיה 2.4 ניתן לניווט | B28: 2.4.2 | C28: כותרת דף | D28: לכל העמודים יש כותרת - page title - ייחודית המתארת את תוכן / פונקציונאליות של העמוד | E28: A | F28: תקין | G28: טכניקות לביצוע קריטריון 2.4.2 | H28: הסבר על קריטריון 2.4.2 | I28: תג <title> נבנה מ-page_title של Shopify, ייחודי לכל עמוד ומתאר את תוכנו; בעמודי רשימה נוספים אליו התג המסונן ומספר העמוד (layout/theme.liquid:20-23).
A29: הנחיה 2.4 ניתן לניווט | B29: 2.4.3 | C29: Focus order | D29: בניווט באמצעות מקלדת (מקש TAB) מעבר הפוקוס לוגי, אינטואיטיבי ומותאם למבנה העמוד | E29: A | G29: טכניקות לביצוע קריטריון 2.4.3 | H29: הסבר על קריטריון 2.4.3 | I29: דרוש מעבר מקלדת ידני על העמוד, והוא לא בוצע - ולכן השורה נותרת ריקה. מה שכן נבדק: אין tabindex חיובי בשום מקום בתבנית, כך שסדר הפוקוס נגזר מסדר ה-DOM; שקופיות לא פעילות בסרגל ההודעות מקבלות tabindex="-1" כדי לא להשאיר קישורים מוסתרים בסדר המקלדת (assets/section-header.js); ובסינון מוצרים הפוקוס נשמר לפני החלפת ה-DOM ומוחזר לאותו פקד עצמו אחריה, כך שהמשתמש אינו מושלך לראש העמוד (assets/facets.js:133-196).
A30: הנחיה 2.4 ניתן לניווט | B30: 2.4.4 | C30: מטרת הקישור (מתוך הקשר) | D30: מטרת הקישור ברורה מתוך טקסט הקישור או מתוך הקונטקסט (המשפט או הפסקה בו הוא נמצא). בכל מקרה שעלול להיווצר חוסר בהירות מסופק title לקישור שמסביר במדוייק ובאופן מלא מהי מטרת הקישור. | E30: A | F30: תקין | G30: טכניקות לביצוע קריטריון 2.4.4 | H30: הסבר על קריטריון 2.4.4 | I30: נסרקו כל מחרוזות הממשק: אין באתר קישור מסוג "לחץ כאן", "קרא עוד" או "כאן" ללא הקשר. קישורי מוצר, אוסף וכתבה נושאים את שם הפריט עצמו. הטקסט הכללי היחיד שנמצא הוא הלחצן "המשך" בעמוד ההתחברות, שמטרתו ברורה מהקשר העמוד שבו הוא יושב.
A31: הנחיה 2.4 ניתן לניווט | B31: 2.4.5 | C31: ריבוי דרכים לאיתור דף באתר | D31: יש יותר מדרך אחת להגיע לעמוד (אלא אם הוא שלב בתהליך או תוצאה של תהליך): דרכים אפשריות - מפת אתר, מנגנון חיפוש, תוכן עניינים, תפריט המכיל את כל העמודים באתר, bookmarks במסמכי PDF. | E31: AA | F31: תקין | G31: טכניקות לביצוע קריטריון 2.4.5 | H31: הסבר על קריטריון 2.4.5 | I31: קיימות יותר מדרך אחת להגיע לכל עמוד: מנוע חיפוש הזמין בכל עמוד ובאזור התמונה הראשי, המציג הצעות מוצרים תוך כדי ההקלדה; תפריט ראשי היררכי; תפריטי הכותרת התחתונה; ועמוד רשימת האוספים.
A32: הנחיה 2.4 ניתן לניווט | B32: 2.4.6 | C32: כותרות ותוויות | D32: כותרות ותוויות ברורות המבהירות בברור את הנושא או המטרה. | E32: AA | F32: תקין | G32: טכניקות לביצוע קריטריון 2.4.6 | H32: הסבר על קריטריון 2.4.6 | I32: כל הכותרות והתוויות באתר מנוסחות בעברית ומבהירות את הנושא או המטרה. נבדק שכל שדה טופס משויך לתווית, וכל לחצן אייקון נושא שם נגיש.
A33: הנחיה 2.4 ניתן לניווט | B33: 2.4.7 | C33: פוקוס נראה לעין | D33: אפקט ויזואלי בפוקוס - כל מרכיב המקבל פוקוס בשימוש במקלדת מקבל אפקט ויזואלי (ע"י הדפדפן או ע"י שינוי עיצוב של הרכיב) | E33: AA | F33: תקין | G33: טכניקות לביצוע קריטריון 2.4.7 | H33: הסבר על קריטריון 2.4.7 | I33: כלל :focus-visible גלובלי נותן לכל רכיב מסגרת 2px בצבע ההדגשה במרווח 2px (assets/base.css:105), בניגודיות 5.08:1 מול לבן - מעל דרישת ה-3:1 לסימון פוקוס. שדות קלט חסרי מסגרת עוטפים את עצמם בטבעת פוקוס ב-:focus-within. בבדיקה זו נמצא ותוקן חריג אחד: שדה הכמות ביטל את המסגרת ולא החזיר דבר במקומה, ולמעטפת שלו לא היה כלל :focus-within - כך שמעבר מקלדת אל שדה הכמות בעמוד המוצר, בעגלה, במגירת העגלה ובהזמנה המהירה לא הראה שום סימן פוקוס. נבדק ב-Chromium לאחר התיקון: מסגרת 2px בצבע ההדגשה, במרווח שלילי כדי שהמעטפת לא תחתוך אותה.
A34: הנחיה 2.4 ניתן לניווט | B34: 2.4.10 | C34: כותרות לקטעים | D34: יש שימוש בכותרות כדי לזהות קטעים (sections) | E34: AA | F34: תקין | G34: טכניקות לביצוע קריטריון 2.4.10 | H34: הסבר על קריטריון 2.4.10 | I34: כל מקטע (section) בעמוד נפתח בכותרת המזהה אותו, בהיררכיה יורדת מ-h1 של העמוד. כותרות המקטעים הן טקסט חי ולא תמונה.
A35: הנחיה 3.1 קריא: יש ליצור תכני טקסט קריאים וניתנים להבנה. | B35: 3.1.1 | C35: השפה בדף | D35: שפת כתיבה - בעמוד מוגדרת שפת הכתיבה (עברית, ערבית, אנגלית) ב HTML TAG. לדוגמא "Lang="he | E35: A | F35: תקין | G35: טכניקות לביצוע קריטריון 3.1.1 | H35: הסבר על קריטריון 3.1.1 | I35: שפת העמוד מוגדרת בתג ה-HTML: <html lang="he" dir="rtl">. השפה נגזרת מ-request.locale.iso_code והכיוון נקבע לפיה (layout/theme.liquid:9), כך שקורא מסך מבטא את הטקסט בעברית ובכיוון הנכון.
A36: הנחיה 3.1 קריא: יש ליצור תכני טקסט קריאים וניתנים להבנה. | B36: 3.1.2 | C36: השפה בחלקים בעמוד | D36: בכל מקום בתוכן בו יש שינוי של שפת הכתיבה מצוין השינוי בקוד באמצעות Lang attribute | E36: A | F36: תקין | G36: טכניקות לביצוע קריטריון 3.1.2 | H36: הסבר על קריטריון 3.1.2 | I36: טקסט הממשק כולו בעברית. שמות מותגים ומספרי דגם באותיות לטיניות (Makita, DHP453) הם שמות פרטיים ומונחים טכניים, הפטורים מהקריטריון. מספרי טלפון וכתובות דוא"ל עטופים ב-dir="ltr" עם בידוד דו-כיווני, כדי שייקראו בסדר שבו נכתבו. הערה: תיאורי מוצר המגיעים מיבואנים עלולים להכיל קטעים באנגלית; אם קיים קטע כזה, יש לסמנו ב-lang="en".
A37: הנחיה 3.2 ניתן לניבוי: יש לגרום לדפי רשת להופיע ולתפקד באופן הניתן לניבוי | B37: 3.2.1 | C37: on focus | D37: כאשר רכיב מקבל פוקוס לא מתרחש שינוי משמעותי (דוגמאות לשינוי משמעותי - פתיחת חלון חדש, העברת מוקד לרכיב אחר, מעבר לדף חדש (כולל כל דבר שנראה למשתמש כאילו בוצע מעבר לדף חדש) או ארגון מחדש של התכנים בדף). | E37: A | F37: תקין | G37: טכניקות לביצוע קריטריון 3.2.1 | H37: הסבר על קריטריון 3.2.1 | I37: קבלת פוקוס אינה גורמת לשינוי הקשר: לא נפתח חלון, לא מועבר מוקד ולא מתבצע מעבר עמוד. לוח הצעות החיפוש נפתח בקבלת פוקוס בשדה, וזו התנהגות ה-combobox המוגדרת ב-ARIA - הפוקוס נשאר בשדה והמשתמש יכול להתעלם מהלוח או לסגור אותו ב-Escape.
A38: הנחיה 3.2 ניתן לניבוי: יש לגרום לדפי רשת להופיע ולתפקד באופן הניתן לניבוי | B38: 3.2.2 | C38: on input | D38: כאשר המשתמש משנה ערך של ממשק משמש לא מתרחש שינוי משמעותי באופן אוטומטי אלא אם כן המשתמש יודע על כך מראש (דוגמאות לשינוי משמעותי - פתיחת חלון חדש, העברת מוקד לרכיב אחר, מעבר לדף חדש (כולל כל דבר שנראה למשתמש כאילו בוצע מעבר לדף חדש) או ארגון מחדש של התכנים בדף). | E38: A | F38: תקין | G38: טכניקות לביצוע קריטריון 3.2.2 | H38: הסבר על קריטריון 3.2.2 | I38: שינוי ערך בסינון, במיון, בבורר הווריאנטים או בשדה הכמות מעדכן את התוצאות או את המחיר - זו ההתנהגות המצופה של הפקדים הללו ואינה שינוי הקשר: הפוקוס נשמר לפני החלפת ה-DOM ומוחזר לאותו פקד אחריה, ומספר התוצאות מוכרז לקורא מסך דרך אזור role="status" (assets/facets.js:133-196, 203). לא נפתח חלון ולא מתבצע מעבר עמוד אוטומטי.
A39: הנחיה 3.2 ניתן לניבוי | B39: 3.2.3 | C39: ניווט עקבי | D39: מנגנוני ניווט באתר מופיעים באותו סדר בכל פעם בה הם חוזרים על עצמם ויש להם אותו זיהוי. | E39: AA | F39: תקין | G39: טכניקות לביצוע קריטריון 3.2.3 | H39: הסבר על קריטריון 3.2.3 | I39: מנגנוני הניווט - כותרת עליונה, תפריט ראשי, חיפוש, עגלה וכותרת תחתונה - מופיעים באותו סדר ובאותו מקום בכל עמוד באתר, ונטענים מאותם מקטעים משותפים.
A40: הנחיה 3.2 ניתן לניבוי | B40: 3.2.4 | C40: זיהוי עקבי | D40: זיהוי רכיבים באופן זהה - כל רכיבי ממשק המשתמש המופיעים במספר רב של עמודים מזוהים באופן זהה | E40: AA | F40: תקין | G40: טכניקות לביצוע קריטריון 3.2.4 | H40: הסבר על קריטריון 3.2.4 | I40: רכיבים החוזרים בעמודים שונים מזוהים באופן זהה: אותו אייקון, אותו טקסט נגיש ואותה התנהגות ללחצן העגלה, לחיפוש, לתפריט הנגישות ולכפתור ההוספה לעגלה בכל מקום שבו הם מופיעים.
...

Sheet עמוד קטגוריה
A1: שם העמוד / מסמך: | B1: עמוד קטגוריה / אוסף מוצרים | C1: כתובת העמוד / מסמך (URL): | D1: https://anshilo.com/collections/all
I2: מקרא: תא ריק בעמודת "תוצאה" משמעו שהקריטריון טרם נבדק, והסיבה מופיעה בהערה. ראו גיליון "סיכום ומקרא".
A3: הנחיה | B3: מס קריטריון | C3: קריטריון בדיקה | D3: תאור הקריטריון | E3: רמה נדרשת בישראל | F3: תוצאה (תקין / לא תקין / לא רלוונטי) | G3: טכניקות לביצוע (באנגלית) (בSilver light, PDF, Flash, HTML) | H3: הסבר על הקריטריון (באנגלית) | I3: הערות הבדיקה, והראיה שעליה היא מבוססת
A4: הנחיה 1.1 חלופה טקסטואלית: יש לספק חלופות טקסטואליות עבור תכנים שאינם טקסטואליים, כך שניתן יהיה להמירן לצורות אחרות להן זקוקים אנשים, כמו אותיות גדולות, ברייל, דיבור, סמלים או שפה פשוטה יותר. | B4: 1.1.1 | C4: תכנים שאינם טקסטואליים | D4: א. לתמונות יש טקסט אלטרנטיבי באמצעות המאפיין alt, המתאר את מהות התמונה (כולל תמונות של כפתורים בטפסים ותמונות של hot spots ב image map.) ב. לתמונות המהוות קישור יש טקסט החלופי מגדיר את מטרת הקישור תמונות ג. לתמונות שאינן מעבירות מידע, כלומר משמשות לדקורציה בלבד, או תמונות שאינן מהוות קישור הכוללת מידע שקיים כבר בטקסט, יש טקסט חלופי ריק ""=alt או שהן מיושמות כרקע ב CSS ד. חלופות שווה ערך לתמונות מורכבות מסופקות בהקשר או בדף הנפרד (צמוד ו / או הפניה באמצעות longdesc). | E4: A | F4: תקין | G4: טכניקות לביצוע קריטריון 1.1.1 | H4: הסבר על קריטריון 1.1.1 | I4: נסרקו כל תבניות התבנית: 39 תגי img, לכולם מאפיין alt. בתמונות מוצר, אוסף וכתבה ה-alt נגזר מה-alt של המדיה, ובהיעדרו משם הפריט (snippets/product-card.liquid:100, snippets/product-media-gallery.liquid:134). 11 תמונות נושאות alt="" ביודעין: הן תמונות קישוט שלצדן מופיעה כבר כותרת טקסט גלויה, או שהן בתוך לחצן הנושא aria-label בעצמו (snippets/product-media-gallery.liquid:305), כך שקורא המסך אינו קורא אותן פעמיים. לתמונות המהוות קישור - הקישור עצמו נושא את שם הפריט. אין באתר תמונות מורכבות (תרשימים, גרפים) הדורשות תיאור ארוך. הערה: התאמת נוסח ה-alt לכל אחת מכ-1,900 תמונות המוצר היא שיקול תוכן ואינה ניתנת לאימות מתוך הקוד.
A5: הנחיה 1.1 חלופה טקסטואלית | B5: 1.1.1 | C5: תכנים שאינם טקסטואליים | D5: מולטימדיה משובצת - embedded - מזוהה באמצעות טקסט חלופי | E5: A | F5: לא רלוונטי | G5: טכניקות לביצוע קריטריון 1.1.1 | H5: הסבר על קריטריון 1.1.1 | I5: לא נמצאה באתר מדיה מבוססת זמן. בתבנית אין נגן אודיו או וידאו, ובדגימה של 30 המוצרים שעודכנו לאחרונה כל פריטי המדיה הם מסוג IMAGE (נשלף מ-Shopify Admin API, שדה mediaContentType). אם יתווסף וידאו או אודיו לאתר - יש לבדוק שורה זו מחדש.
A6: הנחיה 1.1 חלופה טקסטואלית | B6: 1.1.1 | C6: תכנים שאינם טקסטואליים | D6: למדיה מבוססת זמן (וידאו, אודיו, אנימציה), למבחן (שחלופה מלאה תפגע באפקטיביות שלו) ולתוכן שאינו טקסטואלי המהווה חוויה חושית - יש חלופה טקסטואלית, שלכל הפחות, מזהה אותו ומתארת את תוכנו. | E6: A | F6: לא רלוונטי | G6: טכניקות לביצוע קריטריון 1.1.1 | H6: הסבר על קריטריון 1.1.1 | I6: לא נמצאה באתר מדיה מבוססת זמן. בתבנית אין נגן אודיו או וידאו, ובדגימה של 30 המוצרים שעודכנו לאחרונה כל פריטי המדיה הם מסוג IMAGE (נשלף מ-Shopify Admin API, שדה mediaContentType). אם יתווסף וידאו או אודיו לאתר - יש לבדוק שורה זו מחדש. אין באתר גם מבחן או תוכן המהווה חוויה חושית.
A7: הנחיה 1.1 חלופה טקסטואלית | B7: 1.1.1 | C7: תכנים שאינם טקסטואליים | D7: קיימת CHAPTCHA נגישה או חלופה ל CHAPTCHA - אם מטרתו של תוכן שאינו טקסט לוודא שהניגש לתוכן הוא אדם ולא מחשב, יש לספק חלופה טקסטואלית שתזהה את התוכן ותתאר את תכליתו, בנוסף לצורות חלופיות של CAPTCHA המכוונות לתפיסה בחושים אחרים, ומתאימות למוגבלויות שונות. | E7: A | F7: לא רלוונטי | G7: טכניקות לביצוע קריטריון 1.1.1 | H7: הסבר על קריטריון 1.1.1 | I7: אין בעמוד זה מנגנון CAPTCHA.
A8: הנחיה 1.2 מדיה מבוססת-זמן: יש להמציא חלופות עבור מדיה מבוססת-זמן. | B8: 1.2.1 | C8: אודיו-בלבד ווידאו-בלבד (הקלטה מראש) | D8: לאודיו בלבד (מוקלט מראש למשל web cast) - יש תסריט המכיל את כל המידע האודיטורי הרלוונטי להבנת התוכן (הנ"ל יסופק במועד מוקדם ככל האפשר). | E8: AA | F8: לא רלוונטי | G8: טכניקות לביצוע קריטריון 1.2.1 | H8: הסבר על קריטריון 1.2.1 | I8: לא נמצאה באתר מדיה מבוססת זמן. בתבנית אין נגן אודיו או וידאו, ובדגימה של 30 המוצרים שעודכנו לאחרונה כל פריטי המדיה הם מסוג IMAGE (נשלף מ-Shopify Admin API, שדה mediaContentType). אם יתווסף וידאו או אודיו לאתר - יש לבדוק שורה זו מחדש.
A9: הנחיה 1.2 מדיה מבוססת-זמן | B9: 1.2.1 | C9: אודיו-בלבד ווידאו-בלבד (הקלטה מראש) | D9: לוידיאו בלבד (מוקלט מראש) - יש תסריט טקסטואלי או ערוץ אודיו המתאר את הערוץ הוויזואלי. (הנ"ל יסופק במועד מוקדם ככל האפשר). | E9: AA | F9: לא רלוונטי | G9: טכניקות לביצוע קריטריון 1.2.1 | H9: הסבר על קריטריון 1.2.1 | I9: לא נמצאה באתר מדיה מבוססת זמן. בתבנית אין נגן אודיו או וידאו, ובדגימה של 30 המוצרים שעודכנו לאחרונה כל פריטי המדיה הם מסוג IMAGE (נשלף מ-Shopify Admin API, שדה mediaContentType). אם יתווסף וידאו או אודיו לאתר - יש לבדוק שורה זו מחדש.
A10: הנחיה 1.2 מדיה מבוססת-זמן | B10: 1.2.2 | C10: כתוביות | D10: בוידאו הכולל סאונד (קבצי וידאו, סרטוני YouTube וכדומה) יופיעו כתוביות מסונכרנות וחלופה טקסטואלית. (הנ"ל יסופק במועד מוקדם ככל האפשר). | E10: AA | F10: לא רלוונטי | G10: טכניקות לביצוע קריטריון 1.2.2 | H10: הסבר על קריטריון 1.2.2 | I10: לא נמצאה באתר מדיה מבוססת זמן. בתבנית אין נגן אודיו או וידאו, ובדגימה של 30 המוצרים שעודכנו לאחרונה כל פריטי המדיה הם מסוג IMAGE (נשלף מ-Shopify Admin API, שדה mediaContentType). אם יתווסף וידאו או אודיו לאתר - יש לבדוק שורה זו מחדש.
A11: הנחיה 1.2 מדיה מבוססת-זמן | B11: 1.2.3 | C11: תיאורי אודיו או חלופה טקסטואלית למדיה (מוקלטת מראש) | D11: תיאורי אודיו - טקסט (תסריט הכולל תיאורי אודיו) או תיאורי אודיו מלווים את הסרט הוידיאו ומתארים את כל ההתרחשויות הויזואליות שלא ניתן להם תיאור באודיו בסרט עצמו. (לדוגמא להוסיף את המילים "הקהל צוחק" לכתוביות). (הנ"ל יסופק במועד מוקדם ככל האפשר). | E11: AA | F11: לא רלוונטי | G11: טכניקות לביצוע קריטריון 1.2.3 | H11: הסבר על קריטריון 1.2.3 | I11: לא נמצאה באתר מדיה מבוססת זמן. בתבנית אין נגן אודיו או וידאו, ובדגימה של 30 המוצרים שעודכנו לאחרונה כל פריטי המדיה הם מסוג IMAGE (נשלף מ-Shopify Admin API, שדה mediaContentType). אם יתווסף וידאו או אודיו לאתר - יש לבדוק שורה זו מחדש.
A12: הנחיה 1.2 מדיה מבוססת-זמן | B12: 1.2.5 | C12: תיאורי אודיו למדיה (מוקלטת מראש) | D12: תיאורי אודיו מלווים את הסרט הוידיאו ומתארים את כל ההתרחשויות הויזואליות שלא ניתן להם תיאור באודיו בסרט עצמו. (הנ"ל יסופק במועד מוקדם ככל האפשר). | E12: AA | F12: לא רלוונטי | G12: טכניקות לביצוע קריטריון 1.2.5 | H12: הסבר על קריטריון 1.2.5 | I12: לא נמצאה באתר מדיה מבוססת זמן. בתבנית אין נגן אודיו או וידאו, ובדגימה של 30 המוצרים שעודכנו לאחרונה כל פריטי המדיה הם מסוג IMAGE (נשלף מ-Shopify Admin API, שדה mediaContentType). אם יתווסף וידאו או אודיו לאתר - יש לבדוק שורה זו מחדש.
A13: הנחיה 1.3 ניתן להתאמה: יש לבנות תכנים הניתנים להצגה בדרכים שונות (למשל מתווה פשוט יותר) ללא איבוד מידע או מבנה. | B13: 1.3.1 | C13: מידע וקשרים - מידע, מבנה, והקשרים הסמנטיים בין חלקי העמוד המועברים באמצעים ויזואליים (כגון גודל פונט, מסגרות, רקעים וכד') ניתנים להבנה גם באמצעות הקוד: | D13: כתיבת קוד סמנטי: א. כותרות: שימוש <h1> to <h6> לזהות כותרות ב. רשימות: שימוש <ul>, <ol>, and <dl>לרשימות או קבוצות של קישורים (כולל תפריטים) ג. טקסטים מיוחדים: שימוש בסימון סמנטי כדי לסמן טקסט מודגש או מיוחד (לדוגמא <strong>, <code>, <abbr>, <block quote>) ד. טבלאות: שימוש בסימון טבלה להצגת מידע טבלאי (TH לתאי כותרת או scope attribute), וכן שימוש ב caption elements כדי לשייך כותרת טבלת נתונים עם טבלת נתונים, וב Summary element בהתאם לצורך. ה. טפסים: שימוש label elements לשייך תוויות טקסט עם פקדי טופס. מתן תיאור עבור קבוצות של פקדי טופס באמצעות קבוצת שדות וlegend elements. ו. אזורים בעמוד: אזורים בעמוד (תפריט ניווט, איזור ראשי וכד') מוגדרים באמצעות landmarks (רצוי) | E13: A | F13: תקין | G13: טכניקות לביצוע קריטריון 1.3.1 | H13: הסבר על קריטריון 1.3.1 | I13: קוד סמנטי מלא: main[role="main"] (layout/theme.liquid:291), header (sections/header.liquid:71), footer[role="contentinfo"] (sections/footer.liquid:51), nav עם aria-label לכל אזור ניווט, form[role="search"] לחיפוש. רשימות וקבוצות קישורים מסומנות ב-ul/ol. טבלאות: נסרקו כל הטבלאות בתבנית - לכולן תאי כותרת th עם scope. טפסים: נסרקו כל הפקדים - לא נמצא פקד ללא תווית (label, aria-label או aria-labelledby); בורר הווריאנטים מקובץ ב-fieldset עם legend (snippets/product-variant-picker.liquid:93). לא נמצא סימון תצוגתי במקום סמנטי (font, center, big, tt, bgcolor, align).
A14: הנחיה 1.3 ניתן להתאמה | B14: 1.3.1 | C14: מידע וקשרים | D14: קיימת הפרדה מלאה בין תוכן לתצוגה על ידי שימוש ב CSS | E14: A | F14: תקין | G14: טכניקות לביצוע קריטריון 1.3.1 | H14: הסבר על קריטריון 1.3.1 | I14: הפרדה מלאה בין תוכן לתצוגה: כל העיצוב יושב בגיליונות סגנון חיצוניים. שימושי המאפיין style= שנותרו בתבנית מעבירים ערכי custom properties בלבד (למשל --nav-thumb-size), ואינם עיצוב בתוך התגית. לא נמצאו תגיות תצוגה (font, center, big, tt) ולא פריסה מבוססת טבלאות.
A15: הנחיה 1.3 ניתן להתאמה | B15: 1.3.2 | C15: רצף בעל משמעות | D15: כאשר הסדר שבו מוצג תוכן משפיע על המשמעות של התוכן, הרצף יקבע בקוד (שימו לב לסדר המידע בקוד יש השפעה על האופן בו הוא מוקרא לעיוורים העושים שימוש בקוראה מסך לכן חובה לבצע את הבדיקה באמצעות קורא מסך ולוודא שסדר ההקראה לוגי) | E15: A | G15: טכניקות לביצוע קריטריון 1.3.2 | H15: הסבר על קריטריון 1.3.2 | I15: הטופס מחייב לבצע קריטריון זה בבדיקת קורא מסך, וזו לא בוצעה - ולכן השורה נותרת ריקה. מה שכן נבדק: סדר ה-DOM תואם את סדר ההצגה, ולא נמצא שינוי סדר באמצעות CSS, למעט סרגל הכלים של עמוד האוסף (assets/section-collection.css:170, 192, 201): שם לחצן "סינון" מוצג ראשון, המיון שני ומספר התוצאות שלישי, בעוד ב-DOM מספר התוצאות מופיע לפני המיון. מדובר בשלושה פקדים עצמאיים, ומספר התוצאות הוא אזור role="status" המוכרז בנפרד, ולכן להערכתנו אין פגיעה במשמעות - אך יש לאשר זאת בבדיקת קורא מסך.
A16: הנחיה 1.3 ניתן להתאמה | B16: 1.3.3 | C16: מאפייני חישה | D16: הוראות אינן מסתמכות על צבע, צורה, או מיקום על המסך (לדוגמא, "לחץ על הכפתור המרובע כדי להמשיך", או "קרא את הוראות בצבע כחול") הוראות אינן מסתמכות על סאונד (לדוגמא, המתן להישמע צפצוף כדי לעבוד לשלב הבא). | E16: A | F16: תקין | G16: טכניקות לביצוע קריטריון 1.3.3 | H16: הסבר על קריטריון 1.3.3 | I16: נסרקו כל מחרוזות הממשק בקובץ locales/he.default.json: אין באתר הוראה המסתמכת על צבע, על צורה, על מיקום על המסך או על צליל. אין הוראות מסוג "לחץ על הכפתור המרובע" או "קרא את הכתוב באדום".
A17: הנחיה 1.4 בר-הבחנה | B17: 1.4.1 | C17: שימוש בצבע | D17: א. צבע אינו אמצעי יחידי - צבע אינו משמש כאמצעי החזותי היחיד להעברת מידע, סימון פעולה, בקשת תגובה, או הבחנה בפרט חזותי. ב. צבע אינו המבחין היחידי לסימון קישורים. אלא אם כן הבדלי הצבע בין הקישור לטקסט רגיל הוא 1:3 ועיצוב קישור משתנה במרכיב נוסף מלבד צבע on mouse over ו on focus (לדוגמא underline) . | E17: A | F17: תקין | G17: טכניקות לביצוע קריטריון 1.4.1 | H17: הסבר על קריטריון 1.4.1 | I17: מידע אינו מועבר בצבע בלבד: תגי המצב נושאים טקסט ("מבצע", "אזל מהמלאי", "חדש"), וזמינות המוצר מנוסחת במילים ולא בנקודה צבעונית. קישורים: הפרש הניגודיות בין צבע הקישור (#D81E29) לטקסט הגוף (#16202F) נמדד 3.23:1 - מעל ה-3:1 שהקריטריון מתיר - ובנוסף הקישור נבדל במשקל גופן 600, מקבל קו תחתון בריחוף עכבר ומסגרת פוקוס בקבלת פוקוס (assets/base.css:91, 97, 105), כנדרש. קישורים בתוך גוף טקסט (.rte a) נושאים קו תחתון כברירת מחדל של הדפדפן. הערה לשיפור: קישור המונח בתוך פסקה בצבע המשני (#5B6779) נבדל ממנה ב-1.13:1 בלבד ומסתמך שם על משקל הגופן ועל ה-hover/focus בלבד; קו תחתון קבוע לכל הקישורים יסיר את התלות הזו.
A18: הנחיה 1.4 בר-הבחנה | B18: 1.4.2 | C18: שליטה באודיו | D18: שליטה באודיו - קיים מנגנון עצירה או הפסקה, או לשליטה בעוצמה של אודיו המנגן אוטומטית בדף במשך למעלה מ 3 שניות. | E18: A | F18: לא רלוונטי | G18: טכניקות לביצוע קריטריון 1.4.2 | H18: הסבר על קריטריון 1.4.2 | I18: אין בעמוד אודיו המתנגן אוטומטית.
A19: הנחיה 1.4 בר-הבחנה | B19: 1.4.3 | C19: קונטרסט | D19: קונטרסט - עבור כל הטקסטים בעמוד - יחס-קונטרסט של לפחות 4.5:1 בטקסט רגיל. בטקסט גדול (over 18 point or 14 point bold) יחס של לפחות 3:1 (למעט: לוגו, טקסטים המשמשים כרקע לתמונה, טקסטים שלא נראים לאף אחד) אם לא ניתן לעמוד בהנחיה זו מותר על פי התקנות לעשות שימוש בסט צבעים נוסף לאתר העומד בהנחיה. | E19: AA | F19: תקין | G19: טכניקות לביצוע קריטריון 1.4.3 | H19: הסבר על קריטריון 1.4.3 | I19: נמדדו 36 שילובי הצבע שהתבנית מייצרת בפועל - לא רק ההגדרות הגולמיות, אלא גם הגוונים שהפריסה מחשבת במסננים color_mix ו-color_lighten. ארבעה שילובים נכשלו ותוקנו במסגרת בדיקה זו: צבע ההדגשה על גבי הרקע הוורוד הבהיר נמדד 4.47:1 ו-4.06:1, מתחת ל-4.5:1 הנדרש, והוחלף בגוון כהה יותר של אותו הגוון (6.07:1 ו-5.52:1) בקומפוננטות .btn--quiet, .badge--soft, .price__save, ווריאנט נבחר ותג "נבחרו" בסינון. כל שאר השילובים נמדדו 4.69:1 ומעלה, וטקסט הגוף 16.38:1. גבולות שאינם נושאי מידע ואייקונים נבדקו בנפרד מול דרישת ה-3:1 וחורגים ממנה לטובה.
A20: הנחיה 1.4 בר-הבחנה | B20: 1.4.4 | C20: הגדלת טקסט | D20: הגדלת טקסט - כאשר מגדילים את הטקסט ב 200% (פי 2) אין פגיעה במידע ובפונקציונאליות של העמוד. | E20: AA | G20: טכניקות לביצוע קריטריון 1.4.4 | H20: הסבר על קריטריון 1.4.4 | I20: דרושה בדיקה ידנית של הגדלה ל-200% בעמוד עצמו, וזו לא בוצעה - ולכן השורה נותרת ריקה. מה שכן נבדק: הטיפוגרפיה כולה מבוססת יחידות rem ולכן נגררת עם שינוי גודל הגופן, וכך גם עובדים צעדי הגדלת הטקסט שבתפריט הנגישות, המשנים את גודל הגופן של השורש (assets/accessibility.css:135); הערך היחיד בכל גיליונות הסגנון שהוגדר ב-px הוא תווית בתוך ציור SVG בעל viewBox, הנגררת עם הציור ואינה טקסט תוכן; ולא נמצא מכל טקסט בעל גובה קבוע שעלול לחתוך תוכן בהגדלה.
A21: הנחיה 1.4 בר-הבחנה | B21: 1.4.5 | C21: תמונות של טקסט | D21: אם טכנולוגית ניתן להשיג את אותה תצוגה ויזואלית באמצעות טקסט חי (למשל טקסט חי על תמונת רקע) אין להשתמש בטקסט של תמונה. פרט ל: אם קיימת טכניקה בה התמונה של טקסט יכולה להיות מותאמת אישית מבחינה ויזואלית לדרישות של המשתמש; או שהתמונה היא חיונית: הצגה מסוימת של טקסט בתמונה היא חיונית למידע (הערה - לוגו או brand נחשבים לחיוניים). | E21: AA | G21: טכניקות לביצוע קריטריון 1.4.5 | H21: הסבר על קריטריון 1.4.5 | I21: דרושה בדיקה חזותית של התמונות שהועלו לחנות, וזו לא בוצעה: סביבת הבדיקה חסומה מהגעה לתמונות עצמן - ולכן השורה נותרת ריקה. מה שכן ידוע: התבנית מציגה כותרות, כפתורים ומחירים כטקסט חי ולא כתמונה. יש לוודא שבתמונות הבאנר והאריחים אין טקסט "צרוב" שאפשר היה להציג כטקסט חי. הלוגו פטור על פי הקריטריון.
A22: הנחיה 2.1 מקלדת נגישה: יש לאפשר תפקוד מלא ממקלדת. | B22: 2.1.1 | C22: מקלדת | D22: א. כל הפעולות באתר ניתנות לביצוע באמצעות מקלדת לחיצה על מקש tab) ב. מעבר הפוקוס לוגי - מעבר לוגי אינטואיטיבי ומותאם למבנה המסך בין קישורים, פקדים וכדומה. ג. רכיבים שאינם HTML מאפשרים שימוש מלא במקלדת המותאם להתנהגות רכיבי html. ד. כאשר רכיב בדף מקבל פוקוס הדבר לא מעורר שינוי משמעותי בדף (פתיחת דף נוסף, הופעת popup, העברת הפוקוס לרכיב אחר וכדומה) | E22: A | G22: טכניקות לביצוע קריטריון 2.1.1 | H22: הסבר על קריטריון 2.1.1 | I22: דרוש מעבר מקלדת ידני מלא על העמוד, והוא לא בוצע במלואו - ולכן השורה נותרת ריקה. מה שכן נבדק: אין tabindex חיובי בשום מקום בתבנית; אין מטפל אירועים על אלמנט לא אינטראקטיבי (div/span עם onclick); כל הפקדים הם רכיבי HTML מקוריים - button, a, input, select, details/summary - ולא חיקויים; אין role="button" על אלמנט שאינו לחצן. נבדק בפועל בדפדפן: לוח החיפוש (פתיחה, הקלדה, בחירה, Escape, לחיצה בחוץ), רכיבי האקורדיון של תיאור המוצר ושאלות ומשלוחים, סרגל ההודעות וכפתור ההוספה לעגלה בכרטיס המוצר. טרם נבדקו ידנית: מגירת העגלה, מגירת הסינון, גלריית המוצר, ההזמנה המהירה וטפסי החשבון.
A23: הנחיה 2.1 מקלדת נגישה | B23: 2.1.2 | C23: מלכודות מקלדת | D23: הדף אינו כולל "מלכודות מקלדת" (אלמנטים שניתן להגיע אליהם באמצעות המקלדת אך לא ניתן לנווט מהם הלאה) | E23: A | F23: תקין | G23: טכניקות לביצוע קריטריון 2.1.2 | H23: הסבר על קריטריון 2.1.2 | I23: המגירות (תפריט, עגלה, סינון) מלכידות פוקוס בכוונה, כמצופה מחלון מודאלי, אך המלכודת מסתובבת בין הרכיבים ואינה חוסמת יציאה: Escape סוגר את המגירה והפוקוס חוזר ללחצן שפתח אותה (assets/global.js:54-81, 126). נבדק בדפדפן עבור לוח החיפוש ורכיבי האקורדיון. לא נמצא בתבנית רכיב שניתן להיכנס אליו במקלדת ולא לצאת ממנו.
A24: הנחיה 2.2 זמן מספיק: יש לתת למשתמשים מספיק זמן לקרוא ולהשתמש בתכנים. | B24: 2.2.1 | C24: כוונון זמן | D24: בכל מצב בו יש הגבלת זמן לקריאה, תגובה או פעולה (כולל time out), למשתמש ניתנת אפשרות לבטל, להאריך, או להתאים לעצמו את הגבלת הזמן. (למעט מקרים בהם הגבלת הזמן היא מעל 20 שעות). | E24: A | F24: לא רלוונטי | G24: טכניקות לביצוע קריטריון 2.2.1 | H24: הסבר על קריטריון 2.2.1 | I24: אין בעמוד הגבלת זמן לקריאה, לתגובה או להשלמת פעולה, ואין time out המוגדר בתבנית.
A25: הנחיה 2.2 זמן מספיק | B25: 2.2.2 | C25: הפסקה, עצירה, הסתרה | D25: א. ניתן להפסיק, לעצור או להסתיר מידע מהבהב, נע או נגלל (שמופיע במשך יותר מ 5 שניות) ב.יש לקבוע מנגנון שיאפשר למשתמש לעצור, להפסיק או להסתיר מידע המתעדכן באופן אוטומטי, או שיאפשר שליטה בתדירות העדכון, אם המידע (1) מופיע באופן אוטומטי, (2) מוצג במקביל לתוכן אחר; למעט מקרים שבהם העדכון האוטומטי מהותי לפעולה. | E25: A | F25: תקין | G25: טכניקות לביצוע קריטריון 2.2.2 | H25: הסבר על קריטריון 2.2.2 | I25: סרגל ההודעות שבראש כל עמוד מחליף את תוכנו על טיימר, ולכן הקריטריון רלוונטי בכל עמוד. עד לתיקון שבוצע בבדיקה זו לא היה ניתן לעצור אותו: גיליון סגנון אינו יכול לעצור setInterval, ולכן לחצן "עצירת אנימציות ותנועה באתר" שבתפריט הנגישות לא הגיע אליו כלל, וגם הגדרת מערכת ההפעלה נבדקה פעם אחת בלבד בעת טעינת העמוד. כיום הטיימר נגזר משלושה מקורות - בחירת המבקר בתפריט הנגישות, הגדרת הסוחר בתבנית והגדרת מערכת ההפעלה - ונבדק מחדש בכל הפעלה, ואירוע shilo:motion עוצר סבב שכבר בתנועה ברגע הלחיצה ומחזיר את הסרגל לשקופית הראשונה. נבדק ב-Chromium: 3 חילופי שקופית ב-1.1 שניות כשהתנועה מותרת, ו-0 חילופים לאחר הלחיצה, על פני יותר משלושה מרווחי טיימר. בנוסף הסרגל נעצר בריחוף עכבר ובקבלת פוקוס. אין בעמוד תוכן נגלל, מהבהב או מתעדכן אוטומטית אחר.
A26: הנחיה 2.3 התקפים: אין לעצב תכנים באופן הידוע כגורם להתקפים. | B26: 2.3.1 | C26: הבהוב וריצוד | D26: אין הבהוב או ריצוד על במסך בקצב של יותר משלוש פעמים בשנייה או general flash and red flash thresholds. | E26: A | F26: תקין | G26: טכניקות לביצוע קריטריון 2.3.1 | H26: הסבר על קריטריון 2.3.1 | I26: אין באתר תוכן מהבהב או מרצד. אין אנימציה הפועלת בקצב העולה על שלוש פעמים בשנייה, ואין הבזקים בשטח או בעוצמה החורגים מ-general flash ו-red flash thresholds.
A27: הנחיה 2.4 ניתן לניווט: יש לספק דרכים כדי לעזור למשתמשים לנווט, לאתר תכנים, ולקבוע את מקום הימצא. | B27: 2.4.1 | C27: עקיפת בלוקים | D27: קיים מנגנון לעקיפת בלוקים (יחידות קבועות שחוזרות על עצמן במספר עמודים כגון תפריטים, באנרים וכד'). המנגנון תומך בניווט ישיר לתוכן העמוד. | E27: A | F27: תקין | G27: טכניקות לביצוע קריטריון 2.4.1 | H27: הסבר על קריטריון 2.4.1 | I27: קיים קישור "דילוג לתוכן", ראשון בסדר המקלדת, מוסתר עד לקבלת פוקוס ומוביל ישירות ל-#MainContent (layout/theme.liquid:278, 291). בנוסף אזורי הדף מסומנים ב-landmarks, המאפשרים לקורא מסך לדלג בין בלוקים ישירות.
A28: הנחיה 2.4 ניתן לניווט | B28: 2.4.2 | C28: כותרת דף | D28: לכל העמודים יש כותרת - page title - ייחודית המתארת את תוכן / פונקציונאליות של העמוד | E28: A | F28: תקין | G28: טכניקות לביצוע קריטריון 2.4.2 | H28: הסבר על קריטריון 2.4.2 | I28: תג <title> נבנה מ-page_title של Shopify, ייחודי לכל עמוד ומתאר את תוכנו; בעמודי רשימה נוספים אליו התג המסונן ומספר העמוד (layout/theme.liquid:20-23).
A29: הנחיה 2.4 ניתן לניווט | B29: 2.4.3 | C29: Focus order | D29: בניווט באמצעות מקלדת (מקש TAB) מעבר הפוקוס לוגי, אינטואיטיבי ומותאם למבנה העמוד | E29: A | G29: טכניקות לביצוע קריטריון 2.4.3 | H29: הסבר על קריטריון 2.4.3 | I29: דרוש מעבר מקלדת ידני על העמוד, והוא לא בוצע - ולכן השורה נותרת ריקה. מה שכן נבדק: אין tabindex חיובי בשום מקום בתבנית, כך שסדר הפוקוס נגזר מסדר ה-DOM; שקופיות לא פעילות בסרגל ההודעות מקבלות tabindex="-1" כדי לא להשאיר קישורים מוסתרים בסדר המקלדת (assets/section-header.js); ובסינון מוצרים הפוקוס נשמר לפני החלפת ה-DOM ומוחזר לאותו פקד עצמו אחריה, כך שהמשתמש אינו מושלך לראש העמוד (assets/facets.js:133-196).
A30: הנחיה 2.4 ניתן לניווט | B30: 2.4.4 | C30: מטרת הקישור (מתוך הקשר) | D30: מטרת הקישור ברורה מתוך טקסט הקישור או מתוך הקונטקסט (המשפט או הפסקה בו הוא נמצא). בכל מקרה שעלול להיווצר חוסר בהירות מסופק title לקישור שמסביר במדוייק ובאופן מלא מהי מטרת הקישור. | E30: A | F30: תקין | G30: טכניקות לביצוע קריטריון 2.4.4 | H30: הסבר על קריטריון 2.4.4 | I30: נסרקו כל מחרוזות הממשק: אין באתר קישור מסוג "לחץ כאן", "קרא עוד" או "כאן" ללא הקשר. קישורי מוצר, אוסף וכתבה נושאים את שם הפריט עצמו. הטקסט הכללי היחיד שנמצא הוא הלחצן "המשך" בעמוד ההתחברות, שמטרתו ברורה מהקשר העמוד שבו הוא יושב.
A31: הנחיה 2.4 ניתן לניווט | B31: 2.4.5 | C31: ריבוי דרכים לאיתור דף באתר | D31: יש יותר מדרך אחת להגיע לעמוד (אלא אם הוא שלב בתהליך או תוצאה של תהליך): דרכים אפשריות - מפת אתר, מנגנון חיפוש, תוכן עניינים, תפריט המכיל את כל העמודים באתר, bookmarks במסמכי PDF. | E31: AA | F31: תקין | G31: טכניקות לביצוע קריטריון 2.4.5 | H31: הסבר על קריטריון 2.4.5 | I31: קיימות יותר מדרך אחת להגיע לכל עמוד: מנוע חיפוש הזמין בכל עמוד ובאזור התמונה הראשי, המציג הצעות מוצרים תוך כדי ההקלדה; תפריט ראשי היררכי; תפריטי הכותרת התחתונה; ועמוד רשימת האוספים.
A32: הנחיה 2.4 ניתן לניווט | B32: 2.4.6 | C32: כותרות ותוויות | D32: כותרות ותוויות ברורות המבהירות בברור את הנושא או המטרה. | E32: AA | F32: תקין | G32: טכניקות לביצוע קריטריון 2.4.6 | H32: הסבר על קריטריון 2.4.6 | I32: כל הכותרות והתוויות באתר מנוסחות בעברית ומבהירות את הנושא או המטרה. נבדק שכל שדה טופס משויך לתווית, וכל לחצן אייקון נושא שם נגיש.
A33: הנחיה 2.4 ניתן לניווט | B33: 2.4.7 | C33: פוקוס נראה לעין | D33: אפקט ויזואלי בפוקוס - כל מרכיב המקבל פוקוס בשימוש במקלדת מקבל אפקט ויזואלי (ע"י הדפדפן או ע"י שינוי עיצוב של הרכיב) | E33: AA | F33: תקין | G33: טכניקות לביצוע קריטריון 2.4.7 | H33: הסבר על קריטריון 2.4.7 | I33: כלל :focus-visible גלובלי נותן לכל רכיב מסגרת 2px בצבע ההדגשה במרווח 2px (assets/base.css:105), בניגודיות 5.08:1 מול לבן - מעל דרישת ה-3:1 לסימון פוקוס. שדות קלט חסרי מסגרת עוטפים את עצמם בטבעת פוקוס ב-:focus-within. בבדיקה זו נמצא ותוקן חריג אחד: שדה הכמות ביטל את המסגרת ולא החזיר דבר במקומה, ולמעטפת שלו לא היה כלל :focus-within - כך שמעבר מקלדת אל שדה הכמות בעמוד המוצר, בעגלה, במגירת העגלה ובהזמנה המהירה לא הראה שום סימן פוקוס. נבדק ב-Chromium לאחר התיקון: מסגרת 2px בצבע ההדגשה, במרווח שלילי כדי שהמעטפת לא תחתוך אותה.
A34: הנחיה 2.4 ניתן לניווט | B34: 2.4.10 | C34: כותרות לקטעים | D34: יש שימוש בכותרות כדי לזהות קטעים (sections) | E34: AA | F34: תקין | G34: טכניקות לביצוע קריטריון 2.4.10 | H34: הסבר על קריטריון 2.4.10 | I34: כל מקטע (section) בעמוד נפתח בכותרת המזהה אותו, בהיררכיה יורדת מ-h1 של העמוד. כותרות המקטעים הן טקסט חי ולא תמונה.
A35: הנחיה 3.1 קריא: יש ליצור תכני טקסט קריאים וניתנים להבנה. | B35: 3.1.1 | C35: השפה בדף | D35: שפת כתיבה - בעמוד מוגדרת שפת הכתיבה (עברית, ערבית, אנגלית) ב HTML TAG. לדוגמא "Lang="he | E35: A | F35: תקין | G35: טכניקות לביצוע קריטריון 3.1.1 | H35: הסבר על קריטריון 3.1.1 | I35: שפת העמוד מוגדרת בתג ה-HTML: <html lang="he" dir="rtl">. השפה נגזרת מ-request.locale.iso_code והכיוון נקבע לפיה (layout/theme.liquid:9), כך שקורא מסך מבטא את הטקסט בעברית ובכיוון הנכון.
A36: הנחיה 3.1 קריא: יש ליצור תכני טקסט קריאים וניתנים להבנה. | B36: 3.1.2 | C36: השפה בחלקים בעמוד | D36: בכל מקום בתוכן בו יש שינוי של שפת הכתיבה מצוין השינוי בקוד באמצעות Lang attribute | E36: A | F36: תקין | G36: טכניקות לביצוע קריטריון 3.1.2 | H36: הסבר על קריטריון 3.1.2 | I36: טקסט הממשק כולו בעברית. שמות מותגים ומספרי דגם באותיות לטיניות (Makita, DHP453) הם שמות פרטיים ומונחים טכניים, הפטורים מהקריטריון. מספרי טלפון וכתובות דוא"ל עטופים ב-dir="ltr" עם בידוד דו-כיווני, כדי שייקראו בסדר שבו נכתבו. הערה: תיאורי מוצר המגיעים מיבואנים עלולים להכיל קטעים באנגלית; אם קיים קטע כזה, יש לסמנו ב-lang="en".
A37: הנחיה 3.2 ניתן לניבוי: יש לגרום לדפי רשת להופיע ולתפקד באופן הניתן לניבוי | B37: 3.2.1 | C37: on focus | D37: כאשר רכיב מקבל פוקוס לא מתרחש שינוי משמעותי (דוגמאות לשינוי משמעותי - פתיחת חלון חדש, העברת מוקד לרכיב אחר, מעבר לדף חדש (כולל כל דבר שנראה למשתמש כאילו בוצע מעבר לדף חדש) או ארגון מחדש של התכנים בדף). | E37: A | F37: תקין | G37: טכניקות לביצוע קריטריון 3.2.1 | H37: הסבר על קריטריון 3.2.1 | I37: קבלת פוקוס אינה גורמת לשינוי הקשר: לא נפתח חלון, לא מועבר מוקד ולא מתבצע מעבר עמוד. לוח הצעות החיפוש נפתח בקבלת פוקוס בשדה, וזו התנהגות ה-combobox המוגדרת ב-ARIA - הפוקוס נשאר בשדה והמשתמש יכול להתעלם מהלוח או לסגור אותו ב-Escape.
A38: הנחיה 3.2 ניתן לניבוי: יש לגרום לדפי רשת להופיע ולתפקד באופן הניתן לניבוי | B38: 3.2.2 | C38: on input | D38: כאשר המשתמש משנה ערך של ממשק משמש לא מתרחש שינוי משמעותי באופן אוטומטי אלא אם כן המשתמש יודע על כך מראש (דוגמאות לשינוי משמעותי - פתיחת חלון חדש, העברת מוקד לרכיב אחר, מעבר לדף חדש (כולל כל דבר שנראה למשתמש כאילו בוצע מעבר לדף חדש) או ארגון מחדש של התכנים בדף). | E38: A | F38: תקין | G38: טכניקות לביצוע קריטריון 3.2.2 | H38: הסבר על קריטריון 3.2.2 | I38: שינוי ערך בסינון, במיון, בבורר הווריאנטים או בשדה הכמות מעדכן את התוצאות או את המחיר - זו ההתנהגות המצופה של הפקדים הללו ואינה שינוי הקשר: הפוקוס נשמר לפני החלפת ה-DOM ומוחזר לאותו פקד אחריה, ומספר התוצאות מוכרז לקורא מסך דרך אזור role="status" (assets/facets.js:133-196, 203). לא נפתח חלון ולא מתבצע מעבר עמוד אוטומטי.
A39: הנחיה 3.2 ניתן לניבוי | B39: 3.2.3 | C39: ניווט עקבי | D39: מנגנוני ניווט באתר מופיעים באותו סדר בכל פעם בה הם חוזרים על עצמם ויש להם אותו זיהוי. | E39: AA | F39: תקין | G39: טכניקות לביצוע קריטריון 3.2.3 | H39: הסבר על קריטריון 3.2.3 | I39: מנגנוני הניווט - כותרת עליונה, תפריט ראשי, חיפוש, עגלה וכותרת תחתונה - מופיעים באותו סדר ובאותו מקום בכל עמוד באתר, ונטענים מאותם מקטעים משותפים.
A40: הנחיה 3.2 ניתן לניבוי | B40: 3.2.4 | C40: זיהוי עקבי | D40: זיהוי רכיבים באופן זהה - כל רכיבי ממשק המשתמש המופיעים במספר רב של עמודים מזוהים באופן זהה | E40: AA | F40: תקין | G40: טכניקות לביצוע קריטריון 3.2.4 | H40: הסבר על קריטריון 3.2.4 | I40: רכיבים החוזרים בעמודים שונים מזוהים באופן זהה: אותו אייקון, אותו טקסט נגיש ואותה התנהגות ללחצן העגלה, לחיפוש, לתפריט הנגישות ולכפתור ההוספה לעגלה בכל מקום שבו הם מופיעים.
...

Sheet עמוד מוצר
A1: שם העמוד / מסמך: | B1: עמוד מוצר | C1: כתובת העמוד / מסמך (URL): | D1: https://anshilo.com/products/<דוגמה>
I2: מקרא: תא ריק בעמודת "תוצאה" משמעו שהקריטריון טרם נבדק, והסיבה מופיעה בהערה. ראו גיליון "סיכום ומקרא".
A3: הנחיה | B3: מס קריטריון | C3: קריטריון בדיקה | D3: תאור הקריטריון | E3: רמה נדרשת בישראל | F3: תוצאה (תקין / לא תקין / לא רלוונטי) | G3: טכניקות לביצוע (באנגלית) (בSilver light, PDF, Flash, HTML) | H3: הסבר על הקריטריון (באנגלית) | I3: הערות הבדיקה, והראיה שעליה היא מבוססת
